#VRML_SIM R2019a utf8
WorldInfo {
}
Viewpoint {
  orientation -0.6931032800836722 0.6931032800836722 0.1980295085953349 0.75
  position 1.2 1.6 2.3
}
TexturedBackground {
}
TexturedBackgroundLight {
}
Floor {
}
Robot {
  translation 0 0.2 0
  children [
    Shape {
      appearance PBRAppearance {
        baseColor 0.9372549019607843 0.1607843137254902 0.1607843137254902
        roughness 1
        metalness 0
      }
      geometry Box {
        size 0.25 0.08 0.1
      }
    }
    HingeJoint {
      jointParameters HingeJointParameters {
      }
      endPoint Solid {
        rotation 1 0 0 1.5708
        children [
          Shape {
            appearance PBRAppearance {
              baseColor 0 0 0
              roughness 1
              metalness 0
            }
            geometry Cylinder {
              height 0.03
              radius 0.075
            }
          }
        ]
      }
    }
  ]
}
