#VRML_SIM R2019a utf8
WorldInfo {
}
Viewpoint {
  orientation -0.004315657076877484 0.9921884273971218 0.1246735723528492 3.0729291435485298
  position -0.13134846452540974 0.20470419871593254 -1.1531247383824534
}
TexturedBackground {
}
TexturedBackgroundLight {
}
Floor {
  size 20 20
}
Robot {
  translation 0 0.075 0
  children [
    DEF SH_BODY Group {
      children [
        Shape {
          appearance PBRAppearance {
            baseColor 0.9372549019607843 0.1607843137254902 0.1607843137254902
            roughness 1
            metalness 0
          }
          geometry Box {
            size 0.25 0.08 0.1
          }
        }
        Transform {
          translation -0.1075 -0.057 0
          children [
            Shape {
              appearance PBRAppearance {
                baseColor 0.9882352941176471 0.9137254901960784 0.30980392156862746
                roughness 1
                metalness 0
              }
              geometry Sphere {
                radius 0.0175
              }
            }
          ]
        }
      ]
    }
    HingeJoint {
      jointParameters HingeJointParameters {
        axis 0 0 1
        anchor 0.05 0 0.065
      }
      device [
        RotationalMotor {
          name "motor_right"
          maxVelocity 52.4
          maxTorque 0.5932
        }
        PositionSensor {
          name "ps_right"
          resolution 0.005235987
        }
      ]
      endPoint Solid {
        translation 0.05 0 0.065
        rotation 1 0 0 1.5708
        children [
          DEF SH_WHEEL Shape {
            appearance PBRAppearance {
              baseColor 0 0 0
              roughness 1
              metalness 0
            }
            geometry Cylinder {
              height 0.03
              radius 0.075
            }
          }
        ]
        boundingObject USE SH_WHEEL
        physics Physics {
        }
      }
    }
    HingeJoint {
      jointParameters HingeJointParameters {
        axis 0 0 1
        anchor 0.05 0 -0.065
      }
      device [
        RotationalMotor {
          name "motor_left"
          maxVelocity 52.36
          maxTorque 0.5932
        }
        PositionSensor {
          name "ps_left"
          resolution 0.005235987
        }
      ]
      endPoint Solid {
        translation 0.05 0 -0.065
        rotation 1 0 0 1.5806999999999998
        children [
          USE SH_WHEEL
        ]
        name "solid(1)"
        boundingObject USE SH_WHEEL
        physics Physics {
        }
      }
    }
    DistanceSensor {
      translation -0.12619999999999998 0 0
      rotation 0 1 0 3.141592644
      children [
        Shape {
          appearance PBRAppearance {
          }
          geometry Box {
            size 0.04 0.01 0.009999999999999998
          }
        }
      ]
      name "ds"
      lookupTable [
        0 0 0
        0.02 0 0
        5 1660 0
      ]
      resolution 1
    }
  ]
  boundingObject USE SH_BODY
  physics Physics {
    mass 1
  }
  controller "crazybot_Quintal_Nora"
}
